Workbook

Sheet Start here
A1: Thesis literature workbook
A2: Mark Sarman | Final research proposal | due Sunday 11 Oct 2026, 23:59
A4: THE WORKFLOW
A5: Per paper | B5: SAVE in Zotero -> ASK Claude with the right prompt -> CHECK against the PDF -> NOTE the checked rows here.
A6: Reading level | B6: Deep (about 25 papers, chosen to find your moderators): Master prompt. Output goes to Notes AND the list tabs L1-L9. Targeted (about 30): Section prompt. Output goes to Notes. Cite only (rest): Claim-check prompt. Output goes to Notes.
A7: Writing Section 2 | B7: Filter the Notes tab on Theme. Once you have chosen your literature review sections, map themes to sections and combine the rows into one paragraph per idea (concept-centric). Cite with the Zotero Word plugin.
A8: Writing Section 3 | B8: Use the list tabs (L1-L9) and the Counts tab to see what prior studies did, then record your choice in Decisions. Each Decisions row becomes 1-2 sentences: 'Following X and Y, we ...'.
A10: TABS
A11: Reading list | B11: Every paper in reading order (Rank), with day, priority, level, prompt and the fill-in text for the prompt. Update Status as you go.
A12: Parked and dropped | B12: Folder papers outside the reading order, with the reason. Nothing is deleted.
A13: Prompts | B13: The three reading prompts plus a triage prompt for new papers (paste the abstract).
A14: Notes | B14: Everything you will cite, one point per row, labelled by theme (sections are decided later).
A15: L1-L9 | B15: Complete inventories from the Deep papers only (theories, outcomes, distance, moderators, controls, fixed effects, robustness, data, limitations).
A16: Counts | B16: Automatic counts from L4 and L5: how often each control and each moderator appears (tested vs only suggested). Add any control or moderator you find in the empty yellow cells.
A17: Decisions | B17: All design choices. Column E holds current CANDIDATES from our discussions, not decisions. Read first, then write your own final choice in column J and set Status to Decided.
A19: LEGEND
A20: Yellow cells | B20: Columns you fill in.
A21: Grey italic rows | B21: Examples showing the format. Check or delete them; do not cite them unchecked.
A23: RULES
A24: 1 | B24: Only rows with Checked = Yes go into the proposal. Always check numbers, definitions, measures, quotes and page numbers against the PDF.
A25: 2 | B25: Every design choice gets a Decisions row with a source. If there is no source, it is either your contribution (say so) or a risk.
A26: 3 | B26: No new papers after Friday.
A27: 4 | B27: Save a dated copy of the proposal every evening.
A29: WEEK PLAN
A30: Tue 6 Oct | B30: Ranks 1-6: gap and closest work (Li 2014, Bertoni & Groh, Moore first: they are in your folder). Download the rest of the Must papers.
A31: Wed 7 Oct | B31: Ranks 7-15: reviews with research agendas, then the first papers that test moderators. LSEG data check.
A32: Thu 8 Oct | B32: Ranks 16-33: rest of the moderator papers and the moderator theory papers. Evening: look at the Counts tab and choose your moderators in Decisions (column J).
A33: Fri 9 Oct | B33: Ranks 34-57: Targeted papers (outcome, theory, Europe, mechanisms, method). Write Sections 2 and 3.
A34: Sat 10 Oct | B34: Ranks 58+: claim checks while you write introduction, relevance and limitations.
A35: Sun 11 Oct | B35: Reference check, full read-through, submit by 18:00.

Sheet Reading list
A1: Reading list (ranked: read top to bottom)
A2: Progress
B3: Total papers | C3: =COUNTA(D6:D300) -> 108 | D3: Checked or done | E3: =COUNTIF(L6:L300,"Checked")+COUNTIF(L6:L300,"Done") -> 0 | F3: Still to find | G3: =COUNTIF(L6:L300,"To find") -> 50 | H3: Must left | I3: =COUNTIFS(C6:C300,"Must",L6:L300,"<>Done",L6:L300,"<>Checked") -> 84
B4: Provisional ranking. Read in Rank order; 'If time' rows can be skipped. Column J is the text for the [brackets] of the prompt (full ready-made prompts per paper: 'Reading prompts (ranked).md' in this folder). New papers: use the Triage prompt, then add them in the empty rows.
A5: Rank | B5: Day | C5: Priority | D5: Reference | E5: Folder code | F5: File / where | G5: Reading level | H5: Prompt to use | I5: Theme(s) | J5: Fill-in for the [brackets] (copy-paste) | K5: Why here | L5: Status | M5: Notes
A6: 1 | B6: Tue 6 Oct | C6: Must | D6: Li, Vertinsky & Li (2014). National distances, international experience, and venture capital investment performance. Journal of Business Venturing, 29, 471-489. | E6: 2r | F6: 2r ...pdf | G6: Deep | H6: =IF(G6="Deep","Master prompt",IF(G6="Targeted","Section prompt",IF(G6="Cite only","Claim-check prompt",""))) -> Master prompt | I6: Distance; Moderators; Method | J6: how each distance (institutional, cultural, geographic) is measured, how international experience moderates distance, how exit success is coded, and the result for VC industry specialization in Table 2. | K6: A. Gap and closest work: closest model paper (distance -> exit success, moderators tested) | L6: In folder
A7: 2 | B7: Tue 6 Oct | C7: Must | D7: Bertoni, F., & Groh, A. P. (2014). Cross-border investments and venture capital exits in Europe. Corporate Governance: An International Review, 22(2), 84-99. | E7: 3e | F7: 3e ...pdf | G7: Deep | H7: =IF(G7="Deep","Master prompt",IF(G7="Targeted","Section prompt",IF(G7="Cite only","Claim-check prompt",""))) -> Master prompt | I7: Europe and gap; Method | J7: which European countries and years are covered, how cross-border is defined (investor HQ or office), whether distance is measured or only foreign vs domestic, and what the authors say is still unknown for Europe. | K7: A. Gap and closest work: cross-border performance in Europe, decides how narrow your gap sentence must be | L7: In folder
A8: 3 | B8: Tue 6 Oct | C8: Must | D8: Moore, C. B., Payne, G. T., Bell, R. G., & Davis, J. L. (2015). Institutional distance and cross-border venture capital investment flows. Journal of Small Business Management, 53(2), 482-500. | E8: 4e | F8: 4e ...pdf | G8: Deep | H8: =IF(G8="Deep","Master prompt",IF(G8="Targeted","Section prompt",IF(G8="Cite only","Claim-check prompt",""))) -> Master prompt | I8: Europe and gap; Distance | J8: this paper studies flows, not performance: note which institutional dimensions matter, how institutional distance is measured, and whether European countries are in the sample. | K8: A. Gap and closest work: shows distance studied for flows, not performance | L8: In folder
A9: 4 | B9: Tue 6 Oct | C9: Must | D9: Bottazzi, L., Da Rin, M., & Hellmann, T. (2016). The importance of trust for investment: Evidence from venture capital. Review of Financial Studies, 29(9), 2283-2318. | E9: new | F9: To find | G9: Deep | H9: =IF(G9="Deep","Master prompt",IF(G9="Targeted","Section prompt",IF(G9="Cite only","Claim-check prompt",""))) -> Master prompt | I9: Europe and gap; Moderators; Analysis and robustness | J9: how trust between nations is measured (Eurobarometer), whether trust works through selection or performance, why more trust goes with fewer successful exits, and whether other distance measures are included. | K9: A. Gap and closest work: European deals + a country pair feature; biggest overlap risk | L9: To find
A10: 5 | B10: Tue 6 Oct | C10: Must | D10: Compano, R., Johanyak, J., Testa, G., Zhen, Q., & Tuebke, A. (2026). Cross-regional venture capital flows in Europe: The role of entrepreneurial ecosystems and proximity. JRC Working Papers on Corporate R&D and Innovation, 1/2026. | E10: new | F10: To find | G10: Deep | H10: =IF(G10="Deep","Master prompt",IF(G10="Targeted","Section prompt",IF(G10="Cite only","Claim-check prompt",""))) -> Master prompt | I10: Europe and gap; Moderators | J10: the unit of analysis (region pairs), which proximity types are measured, which ecosystem features moderate distance, and whether any performance outcome is studied. | K10: A. Gap and closest work: most recent European distance study (flows) | L10: To find
A11: 6 | B11: Tue 6 Oct | C11: Must | D11: Alhorr, H. S., Moore, C. B., & Payne, G. T. (2008). The impact of economic integration on cross-border venture capital investments: Evidence from the European Union. Entrepreneurship Theory and Practice, 32(5), 897-917. | E11: new | F11: To find | G11: Deep | H11: =IF(G11="Deep","Master prompt",IF(G11="Targeted","Section prompt",IF(G11="Cite only","Claim-check prompt",""))) -> Master prompt | I11: Europe and gap; Moderators | J11: how EU economic integration is measured, whether integration weakens the effect of distance, and the time period and countries. | K11: A. Gap and closest work: EU integration as a pair-level factor | L11: To find
A12: 7 | B12: Wed 7 Oct | C12: Must | D12: Devigne, D., Manigart, S., Vanacker, T., & Mulier, K. (2018). Venture capital internationalization: Synthesis and future research directions. Journal of Economic Surveys, 32(5), 1414-1445. | E12: 0a | F12: 0a ...pdf | G12: Deep | H12: =IF(G12="Deep","Master prompt",IF(G12="Targeted","Section prompt",IF(G12="Cite only","Claim-check prompt",""))) -> Master prompt | I12: Liability of foreignness; Moderators; Europe and gap | J12: the future research agenda: every open question on what weakens or strengthens the liability of foreignness or distance in VC, and on European cross-border VC. | K12: B. Moderator discovery: reviews | L12: In folder
A13: 8 | B13: Wed 7 Oct | C13: Must | D13: Boryniec, P., Li, Y., & Tan, J. (2025). A survey of cross-border venture capital research. Venture Capital, 27(2), 109-170. | E13: 0b | F13: 0b ...pdf | G13: Deep | H13: =IF(G13="Deep","Master prompt",IF(G13="Targeted","Section prompt",IF(G13="Cite only","Claim-check prompt",""))) -> Master prompt | I13: Moderators; Liability of foreignness | J13: the research agenda and any table that lists moderators or contingencies of cross-border VC performance. | K13: B. Moderator discovery: reviews | L13: In folder
A14: 9 | B14: Wed 7 Oct | C14: Must | D14: Hutzschenreuter, T., Kleindienst, I., & Lange, S. (2016). The concept of distance in international business research: A review and research agenda. International Journal of Management Reviews, 18(2), 160-179. | E14: new | F14: To find | G14: Deep | H14: =IF(G14="Deep","Master prompt",IF(G14="Targeted","Section prompt",IF(G14="Cite only","Claim-check prompt",""))) -> Master prompt | I14: Distance; Moderators | J14: their classification of distance dimensions and which moderators of distance effects they call underexplored. | K14: B. Moderator discovery: reviews | L14: To find
A15: 10 | B15: Wed 7 Oct | C15: Must | D15: Beugelsdijk, S., Kostova, T., Kunst, V. E., Spadafora, E., & van Essen, M. (2018). Cultural distance and firm internationalization: A meta-analytical review and theoretical implications. Journal of Management, 44(1), 89-130. | E15: new | F15: To find | G15: Deep | H15: =IF(G15="Deep","Master prompt",IF(G15="Targeted","Section prompt",IF(G15="Cite only","Claim-check prompt",""))) -> Master prompt | I15: Distance; Moderators | J15: which moderators of the cultural distance effect the meta-analysis tests (e.g. experience, entry mode, host country development) and their direction. | K15: B. Moderator discovery: reviews | L15: To find
A16: 11 | B16: Wed 7 Oct | C16: Must | D16: Zhou, C., Kwon, Y., Zhang, Y., Li, J., Kim, J., & Heo, Y. (2021). The role of national distance in international business: A review from 1980 to 2017. Review of International Business and Strategy, 31(2), 153-176. | E16: 0d | F16: 0d ...pdf | G16: Deep | H16: =IF(G16="Deep","Master prompt",IF(G16="Targeted","Section prompt",IF(G16="Cite only","Claim-check prompt",""))) -> Master prompt | I16: Distance; Moderators | J16: which moderators of national distance appear across the reviewed studies and which ones the authors call understudied. | K16: B. Moderator discovery: reviews | L16: In folder
A17: 12 | B17: Wed 7 Oct | C17: Must | D17: Tihanyi, L., Griffith, D. A., & Russell, C. J. (2005). The effect of cultural distance on entry mode choice, international diversification, and MNE performance: A meta-analysis. Journal of International Business Studies, 36(3), 270-283. | E17: new | F17: To find | G17: Deep | H17: =IF(G17="Deep","Master prompt",IF(G17="Targeted","Section prompt",IF(G17="Cite only","Claim-check prompt",""))) -> Master prompt | I17: Distance; Moderators | J17: whether cultural distance relates to performance and which moderators (home country, industry, sample) change that relationship. | K17: B. Moderator discovery: reviews | L17: To find
... A113: 108 | B113: Sat 10 Oct | C113: If time | D113: [Authors to check] (2020). Euro adoption and institutional distance in cross-border VC (difference-in-differences). Asia-Pacific Journal of Business Venturing and Entrepreneurship. | E113: new | F113: To find: koreascience.kr/article/JAKO202007861263641.page | G113: Cite only | H113: =IF(G113="Deep","Master prompt",IF(G113="Targeted","Section prompt",IF(G113="Cite only","Claim-check prompt",""))) -> Claim-check prompt | I113: Europe and gap | J113: Euro adoption changed cross-border VC between member states. [check what is actually found] | K113: J. Claim check while writing (optional) | L113: To find

Sheet Parked and dropped
A1: Parked and dropped (not in the reading order)
A2: Park = do not read before Sunday unless your chosen moderator makes it relevant. Drop = do not use. Nothing is deleted from your folder.
A4: Folder code / file | B4: Paper | C4: Action | D4: Reason
A5: 0f | B5: Jaaskelainen, M. (2012). Venture capital syndication: Synthesis and future directions. International Journal of Management Reviews, 14, 444-463. | C5: Park | D5: Background on syndication. Open only if you pick syndication as a moderator.
A6: 1d | B6: Huang, X., Kenney, M., & Patton, D. (2015). Responding to uncertainty: Syndication partner choice by foreign VC firms in China. Venture Capital, 17(3), 215-235. | C6: Park | D6: China, partner choice. Possible extra gap cite (China focus).
A7: 1f | B7: Plagmann, C., & Lutz, E. (2019). Beggars or choosers? Journal of Banking and Finance, 100, 359-378. | C7: Park | D7: Reputation in international syndicates. Open if reputation becomes a moderator.
A8: 1g | B8: Khurshed, A., Mohamed, A., Schwienbacher, A., & Wang, F. (2020). Do VC firms benefit from international syndicates? JIBS, 51, 986-1007. | C8: Park | D8: Open if international experience becomes a moderator.
A9: 1h | B9: Bellavitis, C., & Rietveld, J. (2019). Prior co-investments and VC syndicate performance. Strategic Entrepreneurship Journal. | C9: Park | D9: Not about distance.
A10: 2c | B10: Zhang, L., & Zhang, X. (2022). The foreign experience and investment performance of venture capitalists. Accounting & Finance, 62, 1675-1714. | C10: Park | D10: Open if foreign experience becomes a moderator.
A11: 2g | B11: Wu, J., Chen, C. R., & Huang, Y. S. (2026). Distant VCs and IPO performance. Applied Economics, 58(30), 5955-5976. | C11: Park | D11: IPO outcome only; possible cite for distance and performance.
A12: 2j | B12: Hong, S., Guerini, M., & Park, H. D. (2025). Global connections, local impacts. ETP, 49(6), 1710-1740. | C12: Park | D12: Open if international syndication experience becomes a moderator.
A13: 2k | B13: Wang, J., et al. (2025). Geographical distance, investment strategies and performance of VC: Chinese enterprises. Spatial Economic Analysis, 20(1), 8-32. | C13: Park | D13: Within-China geographic distance.
A14: 2m | B14: Kim, J. Y., & Park, H. D. (2021). The influence of VC syndicate size on venture performance. Venture Capital, 23(2), 179-203. | C14: Park | D14: Possible source for syndicate size as a control.
A15: 2p | B15: Lee, V. The analysis of cross-border VC networks and investment performances using a logit model. [journal/year unclear] | C15: Park | D15: Unclear source; do not cite unless you verify it.
... A24: ~$ files | B24: Word lock files (start with ~$). | C24: Delete | D24: Not papers; created by Word.

Sheet Prompts
A1: Prompts
A2: How to use | B2: Easiest: open 'Reading prompts (ranked).md' and copy the ready-made prompt for the paper. Or: copy the prompt for the paper's level (Reading list, column H) and paste the fill-in from column J into the [brackets]. Upload the PDF with it. Then CHECK the output against the PDF before copying rows into Notes or L1-L9.
A3: Master prompt (Deep) | B3: You are helping me extract research design information from an academic paper for my master's thesis proposal. My topic (still open, I am reading to decide the design): how distance between the investor's and the startup's country affects the performance of cross-border venture capital investments within Europe, and what weakens or strengthens that effect. My supervisor has set: Europe as scope, the startup's first institutional round, a foreign lead investor, follow-on funding as main outcome, and logit models. Moderators, distance measures and controls are still to be decided, so do not filter on my current ideas: report everything the paper does. Read the attached paper and fill in the template below. Rules: - Only report what the paper actually says. If something is not reported, write "Not reported". Never guess or fill in from general knowledge. - Give a page number for every item. For definitions, measures and key findings, add a short direct quote (max 25 words). - Use (Author, Year) in every bullet and every table row. - PART A: write short bullets I can paste into my proposal and rewrite. End each section with "Use for my thesis:" (copy / adapt / avoid, and why, max 2 sentences). - PART B: be EXHAUSTIVE. List every item the paper uses, also ones that seem irrelevant to my study. Output each as a table row with exactly the columns given, separated by " | ", one row per item, no extra text between rows. === PART A: DESIGN CHOICES (bullets) === A0. Reference: full APA 7 reference; research question (1 sentence); countries/region and time period. A1. Scope and sample: unit of analysis; which financing round(s) and why; definition of "cross-border"/"foreign"; how the lead investor is identified; investor types included/excluded; sector scope; exclusion rules; final sample size. A2. Method: estimation model(s); how interactions are tested and interpreted; standard errors (clustering); selection/endogeneity approach and its justification. A3. Findings (only hypotheses on distance, moderators of distance, or follow-on funding / exit success): result per hypothesis, effect size if reported. A5. Moderators: (a) every moderator the paper TESTS (what it moderates, mechanism, result); (b) every moderator, boundary condition or contingency the authors SUGGEST in the discussion or future research but do not test; (c) which of these could apply to cross-border deals within Europe, and why (max 2 sentences each). A4. Relevance to my thesis: which parts of my proposal it could support (theory, distance, Europe/gap, moderators, method); which design options it suggests that I have not considered yet; one sentence I could cite it for. === PART B: COMPLETE INVENTORIES (table rows) === L1 Theories: Paper | Theory | What it is used to explain | Page L2 Outcomes (main AND alternative): Paper | Outcome | Main or alternative | Exact definition/coding | Time window | Data source | Page L3 Distance and other main independent variables: Paper | Variable | Type (institutional/cultural/geographic/psychic/other) | Indicators used | Formula | Data source and year | Page L4 Moderators (every interaction tested AND every moderator suggested): Paper | Moderator | Tested or suggested | Level (investor/deal/venture/home country/host country/country pair) | Relationship moderated (X -> Y) | Expected sign | Mechanism (1 sentence) | Result | Page L5 Controls (every control variable): Paper | Control | Level (investor/deal/venture/home country/host country/country pair/time) | Measurement | Data source | Page L6 Fixed effects: Paper | Fixed effect | Page L7 Robustness checks: Paper | Check | What it addresses | Result changed? (yes/no) | Page L8 Data sources: Paper | Database | Used for | Coverage problem admitted | Page L9 Limitations and future research: Paper | Type (limitation/future research) | Statement | Relevant to cross-border VC in Europe, moderators of distance, or follow-on funding? (yes/no) | Page Extra focus for this paper (answer this in A3/A5 as well): [FILL IN]
A4: Section prompt (Targeted) | B4: Read the attached paper. What I want to learn from this paper: [FILL IN, e.g. how shared language affects cross-border investment]. Using only what the paper says (write "Not reported" otherwise), give: (1) the full APA 7 reference; (2) research question, sample and method in 3 bullets; (3) the findings or arguments relevant to my section, as short paste-ready bullets with (Author, Year) and page number, plus a direct quote of max 25 words for definitions and key findings; (4) the mechanism the paper gives (why the effect happens), if any; (5) one sentence I could cite it for.
A5: Claim-check prompt (Cite only) | B5: Does the attached paper support this claim: "[FILL IN YOUR SENTENCE]"? Answer yes / partly / no. Quote the passage (max 40 words) with page number. If partly or no, rewrite my sentence so it matches exactly what the paper says. Give the full APA 7 reference.
A6: Triage prompt (new papers) | B6: Below is the abstract of a paper I found. My topic (still open): how distance between the investor's and the startup's country affects the performance of cross-border venture capital investments within Europe, and what weakens or strengthens that effect. I am especially looking for moderators of distance. Based ONLY on the abstract, tell me: (1) Reading level: Deep (tests or suggests moderators of distance or foreignness, or studies cross-border VC performance in Europe), Targeted (supports one theme), Cite only (one fact or claim), or Skip. One reason. (2) Theme(s) from this list: Introduction / relevance; Liability of foreignness; Distance (types, mechanisms); Europe and gap; Moderators; Investor-level factors; Outcome / performance; Sample and data; Measures; Analysis and robustness; Limitations / future research. (3) The fill-in for the matching prompt: Deep = one "Extra focus" line; Targeted = one "What I want to learn" line; Cite only = the one sentence I would cite it for. (4) The APA 7 reference, with [check] on anything you cannot see in the abstract. Abstract: [PASTE]

Sheet Notes
A1: Theme | B1: Paper (Author, Year) | C1: Point / finding / argument | D1: Mechanism (why) | E1: Sample / context | F1: Page | G1: Short quote | H1: Checked | I1: Used in draft
A2: Moderators | B2: EXAMPLE: Grinblatt & Keloharju (2001) | C2: Investors prefer firms that communicate in their own language, holding distance constant. | D2: A shared language lowers the cost of obtaining and trusting information. | E2: Finnish stock investors | F2: check | G2: check | H2: No | I2: No
A3: Distance (types, mechanisms) | B3: EXAMPLE: Li et al. (2014) | C3: Institutional and cultural distance reduce the likelihood of exit success in cross-border VC. | D3: Distance hampers VCs' selection, monitoring and advising, and raises legitimacy costs. | E3: Cross-border first rounds, VentureXpert | F3: check | G3: check | H3: No | I3: No

Sheet L1 Theories
A1: Paper | B1: Theory | C1: What it is used to explain | D1: Page | E1: Checked
A2: EXAMPLE: Li et al. (2014) | B2: Institutional theory | C2: Why institutional distance reduces exit success | D2: check | E2: No

Sheet L2 Outcomes
A1: Paper | B1: Outcome | C1: Main or alternative | D1: Exact definition / coding | E1: Time window | F1: Data source | G1: Page | H1: Checked
A2: EXAMPLE: Li et al. (2014) | B2: Exit success | C2: Main | D2: 1 if the venture went public or was acquired, else 0 | E2: check | F2: VentureXpert | G2: check | H2: No

Sheet L3 Distance
A1: Paper | B1: Variable | C1: Type | D1: Indicators used | E1: Formula | F1: Data source and year | G1: Page | H1: Checked
A2: EXAMPLE: Li et al. (2014) | B2: Institutional distance | C2: institutional | D2: Six WGI dimensions, averaged into a composite | E2: Absolute difference home vs host | F2: WGI (Kaufmann et al.) | G2: check | H2: No

Sheet L4 Moderators
A1: Paper | B1: Moderator | C1: Tested or suggested | D1: Level | E1: Relationship moderated (X -> Y) | F1: Expected sign | G1: Mechanism | H1: Result | I1: Page | J1: Checked
A2: EXAMPLE: Li et al. (2014) | B2: Broad international experience | C2: Tested | D2: investor | E2: Cultural / institutional distance -> exit success | F2: weakens | G2: Experience builds capability to adapt to unfamiliar environments | H2: Supported for institutional distance | I2: check | J2: No

Sheet L5 Controls
A1: Paper | B1: Control | C1: Level | D1: Measurement | E1: Data source | F1: Page | G1: Checked
A2: EXAMPLE: Li et al. (2014) | B2: VC past success | C2: investor | D2: Log number of ventures funded by the VC that went public or were sold in the past five years | E2: VentureXpert | F2: check | G2: No

Sheet L6 Fixed effects
A1: Paper | B1: Fixed effect | C1: Page | D1: Checked
A2: EXAMPLE: Li et al. (2014) | B2: Industry, nation, year | C2: check | D2: No

Sheet L7 Robustness
A1: Paper | B1: Check | C1: What it addresses | D1: Result changed? | E1: Page | F1: Checked
A2: EXAMPLE: Li et al. (2014) | B2: Rule of law instead of composite institutional distance | C2: Measurement of institutional distance | D2: No | E2: check | F2: No

Sheet L8 Data
A1: Paper | B1: Database | C1: Used for | D1: Coverage problem admitted | E1: Page | F1: Checked
A2: EXAMPLE: Li et al. (2014) | B2: VentureXpert | C2: Deal and investor data | D2: check | E2: check | F2: No

Sheet L9 Limitations
A1: Paper | B1: Type | C1: Statement | D1: Relevant to my study? | E1: Page | F1: Checked
A2: EXAMPLE: Bosio et al. (2025) | B2: Future research | C2: Treating the EU as a homogeneous market is a limitation; national differences should be studied. | D2: Yes | E2: check | F2: No

Sheet Counts
A1: Counts (update automatically from L4 and L5)
A2: Provisional starting lists. ADD any control or moderator you find: type its name in an empty yellow cell, spelled exactly as in L4/L5. Counts exclude example rows.
A4: Control (as written in L5) | B4: Papers using it | C4: Where I found it / note | E4: Moderator (as written in L4) | F4: Tested | G4: Suggested | H4: Where I found it / note
A5: VC past success | B5: =IF(A5="","",COUNTIFS('L5 Controls'!$B$2:$B$300,A5,'L5 Controls'!$A$2:$A$300,"<>EXAMPLE*")) -> 0 | E5: International experience | F5: =IF(E5="","",COUNTIFS('L4 Moderators'!$B$2:$B$300,E5,'L4 Moderators'!$C$2:$C$300,"Tested",'L4 Moderators'!$A$2:$A$300,"<>EXAMPLE*")) -> 0 | G5: =IF(E5="","",COUNTIFS('L4 Moderators'!$B$2:$B$300,E5,'L4 Moderators'!$C$2:$C$300,"Suggested",'L4 Moderators'!$A$2:$A$300,"<>EXAMPLE*")) -> 0
A6: VC reputation | B6: =IF(A6="","",COUNTIFS('L5 Controls'!$B$2:$B$300,A6,'L5 Controls'!$A$2:$A$300,"<>EXAMPLE*")) -> 0 | E6: Host country experience | F6: =IF(E6="","",COUNTIFS('L4 Moderators'!$B$2:$B$300,E6,'L4 Moderators'!$C$2:$C$300,"Tested",'L4 Moderators'!$A$2:$A$300,"<>EXAMPLE*")) -> 0 | G6: =IF(E6="","",COUNTIFS('L4 Moderators'!$B$2:$B$300,E6,'L4 Moderators'!$C$2:$C$300,"Suggested",'L4 Moderators'!$A$2:$A$300,"<>EXAMPLE*")) -> 0
A7: VC age | B7: =IF(A7="","",COUNTIFS('L5 Controls'!$B$2:$B$300,A7,'L5 Controls'!$A$2:$A$300,"<>EXAMPLE*")) -> 0 | E7: Local co-investor | F7: =IF(E7="","",COUNTIFS('L4 Moderators'!$B$2:$B$300,E7,'L4 Moderators'!$C$2:$C$300,"Tested",'L4 Moderators'!$A$2:$A$300,"<>EXAMPLE*")) -> 0 | G7: =IF(E7="","",COUNTIFS('L4 Moderators'!$B$2:$B$300,E7,'L4 Moderators'!$C$2:$C$300,"Suggested",'L4 Moderators'!$A$2:$A$300,"<>EXAMPLE*")) -> 0
A8: International experience | B8: =IF(A8="","",COUNTIFS('L5 Controls'!$B$2:$B$300,A8,'L5 Controls'!$A$2:$A$300,"<>EXAMPLE*")) -> 0 | E8: Syndication | F8: =IF(E8="","",COUNTIFS('L4 Moderators'!$B$2:$B$300,E8,'L4 Moderators'!$C$2:$C$300,"Tested",'L4 Moderators'!$A$2:$A$300,"<>EXAMPLE*")) -> 0 | G8: =IF(E8="","",COUNTIFS('L4 Moderators'!$B$2:$B$300,E8,'L4 Moderators'!$C$2:$C$300,"Suggested",'L4 Moderators'!$A$2:$A$300,"<>EXAMPLE*")) -> 0
A9: Host country experience | B9: =IF(A9="","",COUNTIFS('L5 Controls'!$B$2:$B$300,A9,'L5 Controls'!$A$2:$A$300,"<>EXAMPLE*")) -> 0 | E9: Reputation | F9: =IF(E9="","",COUNTIFS('L4 Moderators'!$B$2:$B$300,E9,'L4 Moderators'!$C$2:$C$300,"Tested",'L4 Moderators'!$A$2:$A$300,"<>EXAMPLE*")) -> 0 | G9: =IF(E9="","",COUNTIFS('L4 Moderators'!$B$2:$B$300,E9,'L4 Moderators'!$C$2:$C$300,"Suggested",'L4 Moderators'!$A$2:$A$300,"<>EXAMPLE*")) -> 0
A10: Industry specialization | B10: =IF(A10="","",COUNTIFS('L5 Controls'!$B$2:$B$300,A10,'L5 Controls'!$A$2:$A$300,"<>EXAMPLE*")) -> 0 | E10: Network centrality | F10: =IF(E10="","",COUNTIFS('L4 Moderators'!$B$2:$B$300,E10,'L4 Moderators'!$C$2:$C$300,"Tested",'L4 Moderators'!$A$2:$A$300,"<>EXAMPLE*")) -> 0 | G10: =IF(E10="","",COUNTIFS('L4 Moderators'!$B$2:$B$300,E10,'L4 Moderators'!$C$2:$C$300,"Suggested",'L4 Moderators'!$A$2:$A$300,"<>EXAMPLE*")) -> 0
A11: Syndicate size | B11: =IF(A11="","",COUNTIFS('L5 Controls'!$B$2:$B$300,A11,'L5 Controls'!$A$2:$A$300,"<>EXAMPLE*")) -> 0 | E11: Trust | F11: =IF(E11="","",COUNTIFS('L4 Moderators'!$B$2:$B$300,E11,'L4 Moderators'!$C$2:$C$300,"Tested",'L4 Moderators'!$A$2:$A$300,"<>EXAMPLE*")) -> 0 | G11: =IF(E11="","",COUNTIFS('L4 Moderators'!$B$2:$B$300,E11,'L4 Moderators'!$C$2:$C$300,"Suggested",'L4 Moderators'!$A$2:$A$300,"<>EXAMPLE*")) -> 0
A12: Local co-investor | B12: =IF(A12="","",COUNTIFS('L5 Controls'!$B$2:$B$300,A12,'L5 Controls'!$A$2:$A$300,"<>EXAMPLE*")) -> 0 | E12: Country interconnectedness | F12: =IF(E12="","",COUNTIFS('L4 Moderators'!$B$2:$B$300,E12,'L4 Moderators'!$C$2:$C$300,"Tested",'L4 Moderators'!$A$2:$A$300,"<>EXAMPLE*")) -> 0 | G12: =IF(E12="","",COUNTIFS('L4 Moderators'!$B$2:$B$300,E12,'L4 Moderators'!$C$2:$C$300,"Suggested",'L4 Moderators'!$A$2:$A$300,"<>EXAMPLE*")) -> 0
A13: Local office | B13: =IF(A13="","",COUNTIFS('L5 Controls'!$B$2:$B$300,A13,'L5 Controls'!$A$2:$A$300,"<>EXAMPLE*")) -> 0 | E13: Regulatory institutions | F13: =IF(E13="","",COUNTIFS('L4 Moderators'!$B$2:$B$300,E13,'L4 Moderators'!$C$2:$C$300,"Tested",'L4 Moderators'!$A$2:$A$300,"<>EXAMPLE*")) -> 0 | G13: =IF(E13="","",COUNTIFS('L4 Moderators'!$B$2:$B$300,E13,'L4 Moderators'!$C$2:$C$300,"Suggested",'L4 Moderators'!$A$2:$A$300,"<>EXAMPLE*")) -> 0
A14: Round size | B14: =IF(A14="","",COUNTIFS('L5 Controls'!$B$2:$B$300,A14,'L5 Controls'!$A$2:$A$300,"<>EXAMPLE*")) -> 0 | E14: Entrepreneurial ecosystem | F14: =IF(E14="","",COUNTIFS('L4 Moderators'!$B$2:$B$300,E14,'L4 Moderators'!$C$2:$C$300,"Tested",'L4 Moderators'!$A$2:$A$300,"<>EXAMPLE*")) -> 0 | G14: =IF(E14="","",COUNTIFS('L4 Moderators'!$B$2:$B$300,E14,'L4 Moderators'!$C$2:$C$300,"Suggested",'L4 Moderators'!$A$2:$A$300,"<>EXAMPLE*")) -> 0
A15: Venture age | B15: =IF(A15="","",COUNTIFS('L5 Controls'!$B$2:$B$300,A15,'L5 Controls'!$A$2:$A$300,"<>EXAMPLE*")) -> 0 | E15: Industry specialization | F15: =IF(E15="","",COUNTIFS('L4 Moderators'!$B$2:$B$300,E15,'L4 Moderators'!$C$2:$C$300,"Tested",'L4 Moderators'!$A$2:$A$300,"<>EXAMPLE*")) -> 0 | G15: =IF(E15="","",COUNTIFS('L4 Moderators'!$B$2:$B$300,E15,'L4 Moderators'!$C$2:$C$300,"Suggested",'L4 Moderators'!$A$2:$A$300,"<>EXAMPLE*")) -> 0
A16: Early stage | B16: =IF(A16="","",COUNTIFS('L5 Controls'!$B$2:$B$300,A16,'L5 Controls'!$A$2:$A$300,"<>EXAMPLE*")) -> 0 | E16: Common language | F16: =IF(E16="","",COUNTIFS('L4 Moderators'!$B$2:$B$300,E16,'L4 Moderators'!$C$2:$C$300,"Tested",'L4 Moderators'!$A$2:$A$300,"<>EXAMPLE*")) -> 0 | G16: =IF(E16="","",COUNTIFS('L4 Moderators'!$B$2:$B$300,E16,'L4 Moderators'!$C$2:$C$300,"Suggested",'L4 Moderators'!$A$2:$A$300,"<>EXAMPLE*")) -> 0
A17: Geographic distance | B17: =IF(A17="","",COUNTIFS('L5 Controls'!$B$2:$B$300,A17,'L5 Controls'!$A$2:$A$300,"<>EXAMPLE*")) -> 0 | F17: =IF(E17="","",COUNTIFS('L4 Moderators'!$B$2:$B$300,E17,'L4 Moderators'!$C$2:$C$300,"Tested",'L4 Moderators'!$A$2:$A$300,"<>EXAMPLE*")) | G17: =IF(E17="","",COUNTIFS('L4 Moderators'!$B$2:$B$300,E17,'L4 Moderators'!$C$2:$C$300,"Suggested",'L4 Moderators'!$A$2:$A$300,"<>EXAMPLE*"))
A18: Shared border | B18: =IF(A18="","",COUNTIFS('L5 Controls'!$B$2:$B$300,A18,'L5 Controls'!$A$2:$A$300,"<>EXAMPLE*")) -> 0 | F18: =IF(E18="","",COUNTIFS('L4 Moderators'!$B$2:$B$300,E18,'L4 Moderators'!$C$2:$C$300,"Tested",'L4 Moderators'!$A$2:$A$300,"<>EXAMPLE*")) | G18: =IF(E18="","",COUNTIFS('L4 Moderators'!$B$2:$B$300,E18,'L4 Moderators'!$C$2:$C$300,"Suggested",'L4 Moderators'!$A$2:$A$300,"<>EXAMPLE*"))
A19: Common language | B19: =IF(A19="","",COUNTIFS('L5 Controls'!$B$2:$B$300,A19,'L5 Controls'!$A$2:$A$300,"<>EXAMPLE*")) -> 0 | F19: =IF(E19="","",COUNTIFS('L4 Moderators'!$B$2:$B$300,E19,'L4 Moderators'!$C$2:$C$300,"Tested",'L4 Moderators'!$A$2:$A$300,"<>EXAMPLE*")) | G19: =IF(E19="","",COUNTIFS('L4 Moderators'!$B$2:$B$300,E19,'L4 Moderators'!$C$2:$C$300,"Suggested",'L4 Moderators'!$A$2:$A$300,"<>EXAMPLE*"))
A20: Host GDP | B20: =IF(A20="","",COUNTIFS('L5 Controls'!$B$2:$B$300,A20,'L5 Controls'!$A$2:$A$300,"<>EXAMPLE*")) -> 0 | F20: =IF(E20="","",COUNTIFS('L4 Moderators'!$B$2:$B$300,E20,'L4 Moderators'!$C$2:$C$300,"Tested",'L4 Moderators'!$A$2:$A$300,"<>EXAMPLE*")) | G20: =IF(E20="","",COUNTIFS('L4 Moderators'!$B$2:$B$300,E20,'L4 Moderators'!$C$2:$C$300,"Suggested",'L4 Moderators'!$A$2:$A$300,"<>EXAMPLE*"))
A21: Host stock market development | B21: =IF(A21="","",COUNTIFS('L5 Controls'!$B$2:$B$300,A21,'L5 Controls'!$A$2:$A$300,"<>EXAMPLE*")) -> 0 | F21: =IF(E21="","",COUNTIFS('L4 Moderators'!$B$2:$B$300,E21,'L4 Moderators'!$C$2:$C$300,"Tested",'L4 Moderators'!$A$2:$A$300,"<>EXAMPLE*")) | G21: =IF(E21="","",COUNTIFS('L4 Moderators'!$B$2:$B$300,E21,'L4 Moderators'!$C$2:$C$300,"Suggested",'L4 Moderators'!$A$2:$A$300,"<>EXAMPLE*"))
A22: Host VC volume | B22: =IF(A22="","",COUNTIFS('L5 Controls'!$B$2:$B$300,A22,'L5 Controls'!$A$2:$A$300,"<>EXAMPLE*")) -> 0 | F22: =IF(E22="","",COUNTIFS('L4 Moderators'!$B$2:$B$300,E22,'L4 Moderators'!$C$2:$C$300,"Tested",'L4 Moderators'!$A$2:$A$300,"<>EXAMPLE*")) | G22: =IF(E22="","",COUNTIFS('L4 Moderators'!$B$2:$B$300,E22,'L4 Moderators'!$C$2:$C$300,"Suggested",'L4 Moderators'!$A$2:$A$300,"<>EXAMPLE*"))
A23: Exit market conditions | B23: =IF(A23="","",COUNTIFS('L5 Controls'!$B$2:$B$300,A23,'L5 Controls'!$A$2:$A$300,"<>EXAMPLE*")) -> 0 | F23: =IF(E23="","",COUNTIFS('L4 Moderators'!$B$2:$B$300,E23,'L4 Moderators'!$C$2:$C$300,"Tested",'L4 Moderators'!$A$2:$A$300,"<>EXAMPLE*")) | G23: =IF(E23="","",COUNTIFS('L4 Moderators'!$B$2:$B$300,E23,'L4 Moderators'!$C$2:$C$300,"Suggested",'L4 Moderators'!$A$2:$A$300,"<>EXAMPLE*"))
A24: Investor type | B24: =IF(A24="","",COUNTIFS('L5 Controls'!$B$2:$B$300,A24,'L5 Controls'!$A$2:$A$300,"<>EXAMPLE*")) -> 0 | F24: =IF(E24="","",COUNTIFS('L4 Moderators'!$B$2:$B$300,E24,'L4 Moderators'!$C$2:$C$300,"Tested",'L4 Moderators'!$A$2:$A$300,"<>EXAMPLE*")) | G24: =IF(E24="","",COUNTIFS('L4 Moderators'!$B$2:$B$300,E24,'L4 Moderators'!$C$2:$C$300,"Suggested",'L4 Moderators'!$A$2:$A$300,"<>EXAMPLE*"))
B25: =IF(A25="","",COUNTIFS('L5 Controls'!$B$2:$B$300,A25,'L5 Controls'!$A$2:$A$300,"<>EXAMPLE*")) | F25: =IF(E25="","",COUNTIFS('L4 Moderators'!$B$2:$B$300,E25,'L4 Moderators'!$C$2:$C$300,"Tested",'L4 Moderators'!$A$2:$A$300,"<>EXAMPLE*")) | G25: =IF(E25="","",COUNTIFS('L4 Moderators'!$B$2:$B$300,E25,'L4 Moderators'!$C$2:$C$300,"Suggested",'L4 Moderators'!$A$2:$A$300,"<>EXAMPLE*"))
B26: =IF(A26="","",COUNTIFS('L5 Controls'!$B$2:$B$300,A26,'L5 Controls'!$A$2:$A$300,"<>EXAMPLE*")) | F26: =IF(E26="","",COUNTIFS('L4 Moderators'!$B$2:$B$300,E26,'L4 Moderators'!$C$2:$C$300,"Tested",'L4 Moderators'!$A$2:$A$300,"<>EXAMPLE*")) | G26: =IF(E26="","",COUNTIFS('L4 Moderators'!$B$2:$B$300,E26,'L4 Moderators'!$C$2:$C$300,"Suggested",'L4 Moderators'!$A$2:$A$300,"<>EXAMPLE*"))
B27: =IF(A27="","",COUNTIFS('L5 Controls'!$B$2:$B$300,A27,'L5 Controls'!$A$2:$A$300,"<>EXAMPLE*")) | F27: =IF(E27="","",COUNTIFS('L4 Moderators'!$B$2:$B$300,E27,'L4 Moderators'!$C$2:$C$300,"Tested",'L4 Moderators'!$A$2:$A$300,"<>EXAMPLE*")) | G27: =IF(E27="","",COUNTIFS('L4 Moderators'!$B$2:$B$300,E27,'L4 Moderators'!$C$2:$C$300,"Suggested",'L4 Moderators'!$A$2:$A$300,"<>EXAMPLE*"))
B28: =IF(A28="","",COUNTIFS('L5 Controls'!$B$2:$B$300,A28,'L5 Controls'!$A$2:$A$300,"<>EXAMPLE*")) | F28: =IF(E28="","",COUNTIFS('L4 Moderators'!$B$2:$B$300,E28,'L4 Moderators'!$C$2:$C$300,"Tested",'L4 Moderators'!$A$2:$A$300,"<>EXAMPLE*")) | G28: =IF(E28="","",COUNTIFS('L4 Moderators'!$B$2:$B$300,E28,'L4 Moderators'!$C$2:$C$300,"Suggested",'L4 Moderators'!$A$2:$A$300,"<>EXAMPLE*"))
B29: =IF(A29="","",COUNTIFS('L5 Controls'!$B$2:$B$300,A29,'L5 Controls'!$A$2:$A$300,"<>EXAMPLE*")) | F29: =IF(E29="","",COUNTIFS('L4 Moderators'!$B$2:$B$300,E29,'L4 Moderators'!$C$2:$C$300,"Tested",'L4 Moderators'!$A$2:$A$300,"<>EXAMPLE*")) | G29: =IF(E29="","",COUNTIFS('L4 Moderators'!$B$2:$B$300,E29,'L4 Moderators'!$C$2:$C$300,"Suggested",'L4 Moderators'!$A$2:$A$300,"<>EXAMPLE*"))
B30: =IF(A30="","",COUNTIFS('L5 Controls'!$B$2:$B$300,A30,'L5 Controls'!$A$2:$A$300,"<>EXAMPLE*")) | F30: =IF(E30="","",COUNTIFS('L4 Moderators'!$B$2:$B$300,E30,'L4 Moderators'!$C$2:$C$300,"Tested",'L4 Moderators'!$A$2:$A$300,"<>EXAMPLE*")) | G30: =IF(E30="","",COUNTIFS('L4 Moderators'!$B$2:$B$300,E30,'L4 Moderators'!$C$2:$C$300,"Suggested",'L4 Moderators'!$A$2:$A$300,"<>EXAMPLE*"))
B31: =IF(A31="","",COUNTIFS('L5 Controls'!$B$2:$B$300,A31,'L5 Controls'!$A$2:$A$300,"<>EXAMPLE*")) | F31: =IF(E31="","",COUNTIFS('L4 Moderators'!$B$2:$B$300,E31,'L4 Moderators'!$C$2:$C$300,"Tested",'L4 Moderators'!$A$2:$A$300,"<>EXAMPLE*")) | G31: =IF(E31="","",COUNTIFS('L4 Moderators'!$B$2:$B$300,E31,'L4 Moderators'!$C$2:$C$300,"Suggested",'L4 Moderators'!$A$2:$A$300,"<>EXAMPLE*"))
B32: =IF(A32="","",COUNTIFS('L5 Controls'!$B$2:$B$300,A32,'L5 Controls'!$A$2:$A$300,"<>EXAMPLE*")) | F32: =IF(E32="","",COUNTIFS('L4 Moderators'!$B$2:$B$300,E32,'L4 Moderators'!$C$2:$C$300,"Tested",'L4 Moderators'!$A$2:$A$300,"<>EXAMPLE*")) | G32: =IF(E32="","",COUNTIFS('L4 Moderators'!$B$2:$B$300,E32,'L4 Moderators'!$C$2:$C$300,"Suggested",'L4 Moderators'!$A$2:$A$300,"<>EXAMPLE*"))
B33: =IF(A33="","",COUNTIFS('L5 Controls'!$B$2:$B$300,A33,'L5 Controls'!$A$2:$A$300,"<>EXAMPLE*")) | F33: =IF(E33="","",COUNTIFS('L4 Moderators'!$B$2:$B$300,E33,'L4 Moderators'!$C$2:$C$300,"Tested",'L4 Moderators'!$A$2:$A$300,"<>EXAMPLE*")) | G33: =IF(E33="","",COUNTIFS('L4 Moderators'!$B$2:$B$300,E33,'L4 Moderators'!$C$2:$C$300,"Suggested",'L4 Moderators'!$A$2:$A$300,"<>EXAMPLE*"))
B34: =IF(A34="","",COUNTIFS('L5 Controls'!$B$2:$B$300,A34,'L5 Controls'!$A$2:$A$300,"<>EXAMPLE*")) | F34: =IF(E34="","",COUNTIFS('L4 Moderators'!$B$2:$B$300,E34,'L4 Moderators'!$C$2:$C$300,"Tested",'L4 Moderators'!$A$2:$A$300,"<>EXAMPLE*")) | G34: =IF(E34="","",COUNTIFS('L4 Moderators'!$B$2:$B$300,E34,'L4 Moderators'!$C$2:$C$300,"Suggested",'L4 Moderators'!$A$2:$A$300,"<>EXAMPLE*"))
B35: =IF(A35="","",COUNTIFS('L5 Controls'!$B$2:$B$300,A35,'L5 Controls'!$A$2:$A$300,"<>EXAMPLE*")) | F35: =IF(E35="","",COUNTIFS('L4 Moderators'!$B$2:$B$300,E35,'L4 Moderators'!$C$2:$C$300,"Tested",'L4 Moderators'!$A$2:$A$300,"<>EXAMPLE*")) | G35: =IF(E35="","",COUNTIFS('L4 Moderators'!$B$2:$B$300,E35,'L4 Moderators'!$C$2:$C$300,"Suggested",'L4 Moderators'!$A$2:$A$300,"<>EXAMPLE*"))
B36: =IF(A36="","",COUNTIFS('L5 Controls'!$B$2:$B$300,A36,'L5 Controls'!$A$2:$A$300,"<>EXAMPLE*")) | F36: =IF(E36="","",COUNTIFS('L4 Moderators'!$B$2:$B$300,E36,'L4 Moderators'!$C$2:$C$300,"Tested",'L4 Moderators'!$A$2:$A$300,"<>EXAMPLE*")) | G36: =IF(E36="","",COUNTIFS('L4 Moderators'!$B$2:$B$300,E36,'L4 Moderators'!$C$2:$C$300,"Suggested",'L4 Moderators'!$A$2:$A$300,"<>EXAMPLE*"))
... B64: =IF(A64="","",COUNTIFS('L5 Controls'!$B$2:$B$300,A64,'L5 Controls'!$A$2:$A$300,"<>EXAMPLE*")) | F64: =IF(E64="","",COUNTIFS('L4 Moderators'!$B$2:$B$300,E64,'L4 Moderators'!$C$2:$C$300,"Tested",'L4 Moderators'!$A$2:$A$300,"<>EXAMPLE*")) | G64: =IF(E64="","",COUNTIFS('L4 Moderators'!$B$2:$B$300,E64,'L4 Moderators'!$C$2:$C$300,"Suggested",'L4 Moderators'!$A$2:$A$300,"<>EXAMPLE*"))
A67: Moderators by level
A68: Level | B68: Tested | C68: Suggested
A69: investor | B69: =COUNTIFS('L4 Moderators'!$D$2:$D$300,A69,'L4 Moderators'!$C$2:$C$300,"Tested",'L4 Moderators'!$A$2:$A$300,"<>EXAMPLE*") -> 0 | C69: =COUNTIFS('L4 Moderators'!$D$2:$D$300,A69,'L4 Moderators'!$C$2:$C$300,"Suggested",'L4 Moderators'!$A$2:$A$300,"<>EXAMPLE*") -> 0
A70: deal | B70: =COUNTIFS('L4 Moderators'!$D$2:$D$300,A70,'L4 Moderators'!$C$2:$C$300,"Tested",'L4 Moderators'!$A$2:$A$300,"<>EXAMPLE*") -> 0 | C70: =COUNTIFS('L4 Moderators'!$D$2:$D$300,A70,'L4 Moderators'!$C$2:$C$300,"Suggested",'L4 Moderators'!$A$2:$A$300,"<>EXAMPLE*") -> 0
...

Sheet Decisions
A1: # | B1: Area | C1: Design choice | D1: Options considered | E1: Current candidate (not final) | F1: Why this candidate | G1: Sources to check | H1: Status | I1: Fallback if data fails | J1: Final decision (after reading)
A2: 1 | B2: Scope & sample | C2: Countries | D2: EU only; EU + UK + CH + NO | E2: Europe = EU27 + UK + Switzerland + Norway | F2: Supervisor (Meeting 2); EU membership changes over time; UK is a major VC market | G2: Alhorr et al. (2008); Moore et al. (2015); Bosio et al. (2025) | H2: Set by supervisor
A3: 2 | B3: Scope & sample | C3: Small-market rule | D3: No rule; min 20 / 30 deals per host country | E3: Drop host countries with fewer than 30 foreign-led first rounds | F3: Supervisor: drop markets too small to be meaningful | G3: Check practice in Li et al. (2014), Nahata et al. (2014) | H3: Candidate | I3: Threshold of 20
A4: 3 | B4: Scope & sample | C4: Time period | D4: Depends on LSEG coverage | E4: About 2005-2022 (follow-on outcome); exit cohort up to about 2017 | F4: 24 months to raise a round; 7+ years to exit | G4: Li et al. (2014); Bertoni & Groh (2014) | H4: Candidate | I4: Shorter window
A5: 4 | B5: Scope & sample | C5: Unit of analysis | D5: Deal; startup; startup-investor pair | E5: Startup's first institutional round (one observation per startup) | F5: Matches first-round focus | G5: Li et al. (2014) | H5: Candidate
A6: 5 | B6: Scope & sample | C6: Which round | D6: All rounds; first round; first institutional round | E6: First institutional VC round | F6: Path dependence; distance frictions appear at first investment (supervisor) | G6: Gompers (1995); Li et al. (2014); Milanov & Shepherd (2013) | H6: Set by supervisor
A7: 6 | B7: Scope & sample | C7: Cross-border definition | D7: Any foreign investor; foreign lead | E7: Lead VC headquartered in a different European country than the startup | F7: Supervisor: lead VC is the foreign investor | G7: Li et al. (2014); Devigne et al. (2018) | H7: Set by supervisor | I7: Any foreign VC in the round
A8: 7 | B8: Scope & sample | C8: Lead investor identification | D8: Largest amount; first investor; most rounds | E8: Largest amount invested in the round | F8: Standard in VC research | G8: Nahata (2008) | H8: Candidate | I8: Investor in most subsequent rounds
A9: 8 | B9: Scope & sample | C9: Investor types | D9: Independent VC only; all types | E9: All VC types, investor type as control | F9: Captive investors are common in Europe | G9: Bertoni et al. (2015) | H9: Candidate | I9: Independent VC only
A10: 9 | B10: Scope & sample | C10: Sector scope | D10: Life sciences; high-tech; all sectors | E10: All sectors with industry fixed effects | F10: Generalizability; sample size | G10: Li et al. (2014) | H10: Candidate
A11: 10 | B11: Data | C11: Deal database | D11: LSEG; Dealroom; Crunchbase; PitchBook | E11: LSEG Workspace (VentureXpert) | F11: Available via library; used in close studies | G11: Northemann (2023); Retterath & Braun (2020) | H11: Candidate | I11: Dealroom for validation
A12: 11 | B12: Data | C12: Investor location | D12: HQ; investing office | E12: Headquarters; robustness: re-code multi-office VCs or control for local office | F12: Supervisor suggested HQ as default; robustness step makes it a 9 | G12: Chen et al. (2010); Devigne et al. (2018) | H12: Supervisor suggestion
A13: 12 | B13: Data | C13: Other data sources | E13: WGI; Hofstede; CEPII GeoDist; bilateral trade data; Eurobarometer trust (robustness) | F13: Standard sources for distance and pair measures | G13: Mayer & Zignago (2011); Berry et al. (2010) | H13: Candidate
A14: 13 | B14: Outcome | C14: Main outcome | D14: Follow-on round 24 / 36 months; exit success | E14: Follow-on round within 24 months (1/0) | F14: Supervisor; more recent deals usable; direct effect of first round | G14: Hochberg et al. (2007); Alexy et al. (2012); Devigne et al. (2016) | H14: Set by supervisor | I14: 36 months
A15: 14 | B15: Outcome | C15: Insider-round robustness | E15: Follow-on round with at least one new investor | F15: Foreign lead may decide to follow on itself | G15: Devigne et al. (2016) | H15: Candidate
A16: 15 | B16: Outcome | C16: Secondary outcomes | E16: Exit success (IPO/M&A); time to exit (Cox) | F16: Comparability with prior work | G16: Li et al. (2014); Espenlaub et al. (2015) | H16: Candidate
A17: 16 | B17: Independent variables | C17: Institutional distance | D17: Composite WGI; Mahalanobis; Scott pillars | E17: Mahalanobis on WGI regulatory quality, rule of law, government effectiveness; robustness: rule of law only | F17: Formal, codified rules; supervisor asked for precision on which institutions | G17: Berry et al. (2010); Mingo et al. (2018); Li et al. (2014) | H17: Candidate
A18: 17 | B18: Independent variables | C18: Cultural distance | D18: Hofstede; GLOBE | E18: Kogut & Singh index on Hofstede; robustness: GLOBE | F18: Most used measure | G18: Kogut & Singh (1988); Beugelsdijk et al. (2018) | H18: Candidate
A19: 18 | B19: Independent variables | C19: Geographic distance | E19: Control: ln km between capitals | F19: Short within Europe; overlaps with shared border | G19: Mingo et al. (2018); Mayer & Zignago (2011) | H19: Candidate
A20: 19 | B20: Moderators | C20: Shared language | D20: Official; spoken (9%) | E20: CEPII common official language; robustness: spoken language | F20: Lowers cost of information and trust; European bridge | G20: Grinblatt & Keloharju (2001); Dow & Karunaratna (2006) | H20: Candidate
A21: 20 | B21: Moderators | C21: Country ties | D21: Trade intensity; trust; prior VC deals | E21: Bilateral trade intensity, 5-year average before the deal; robustness: prior VC deals between the pair; trust as control | F21: Familiarity with the other country's institutions; trust has selection issues (Bottazzi) | G21: Alvarez-Garrido & Guler (2018); Portes & Rey (2005); Guiso et al. (2009); Bottazzi et al. (2016) | H21: Candidate
A22: 21 | B22: Moderators | C22: Industry specialization | D22: Share of investments; Herfindahl | E22: Lead VC's share of past-5-year investments in the startup's industry | F22: Portable industry knowledge changes the slope | G22: Li et al. (2014); Gompers et al. (2009); Matusik & Fitza (2012) | H22: Candidate
A23: 22 | B23: Controls | C23: Investor level | E23: International experience (+ x distance), reputation, VC age, investor type, local office | F23: From Counts tab | G23: Li et al. (2014); Nahata (2008) | H23: Candidate
A24: 23 | B24: Controls | C24: Deal level | E24: Round size, syndicate size, local co-investor | F24: From Counts tab | G24: Kim & Park (2021); Tykvova & Schertler (2014) | H24: Candidate
A25: 24 | B25: Controls | C25: Startup level | E25: Venture age at round, industry | F25: From Counts tab | G25: Li et al. (2014) | H25: Candidate
A26: 25 | B26: Controls | C26: Country / pair level | E26: Shared border, geographic distance, host exit conditions, host VC volume, host institutional quality, bilateral trust | F26: From Counts tab; JRC (2026) ecosystems | G26: Bertoni & Groh (2014); Dai & Nahata (2016); Beugelsdijk et al. (2018) | H26: Candidate
A27: 26 | B27: Controls | C27: Fixed effects | E27: Year, industry, investor-country, host-country | F27: Standard | G27: Li et al. (2014) | H27: Candidate
A28: 27 | B28: Method | C28: Estimation model | D28: Logit; probit; LPM | E28: Logit; robustness probit and linear probability model | F28: Supervisor | G28: Hoetker (2007); Liu & Maula (2021) | H28: Set by supervisor
A29: 28 | B29: Method | C29: Interactions | D29: Coefficients; marginal effects | E29: Marginal effects at low and high moderator values | F29: Logit interaction coefficients can mislead | G29: Ai & Norton (2003); Hoetker (2007) | H29: Candidate
A30: 29 | B30: Method | C30: Standard errors | D30: By VC; by country pair | E30: Clustered by lead VC | F30: Repeated deals by the same VC | G30: Check in L-tabs | H30: Candidate | I30: Country pair
A31: 30 | B31: Method | C31: Selection | D31: None; Heckman | E31: Heckman if foreign-led deals differ systematically; first-stage variable to choose | F31: Distant investors may select better startups (Bottazzi et al., 2016) | G31: Certo et al. (2016); Wolfolds & Siegel (2019) | H31: Candidate | I31: Discuss as limitation
A32: 31 | B32: Method | C32: Robustness checks | E32: Office re-coding; 36-month window; new-investor rounds; rule of law only; GLOBE; exclude UK and largest investor country; exit outcomes | F32: Menu from L7 | G32: Li et al. (2014); Liu & Maula (2021) | H32: Candidate
